Workbook

Sheet README
B1: Security Assessment Operating System (SAOS)
B2: Assessment workbook v0.1 (Phase 0 + Server Security pilot) | built 2025-11-28
B4: Purpose
B5: Vendor-neutral, framework-driven assessment toolkit for client engagements. Every control carries a purpose, evidence requirements, test procedure, maturity anchors, risk rating, remediation guidance and framework mappings.
B6: This release contains the Phase 0 foundations (methodology, risk and maturity models, registers, dashboard) and the first completed domain: Server Security (60 controls). See Domain_Registry for build status of all domains.
B8: How to run an engagement
B9: 1. Scope: complete the Scope sheet (client, tier, platforms, domains). Applicable? and target maturity pre-fill from it.
B10: 2. Evidence: send Evidence_Requests to the client; log each received item in Evidence_Register and link its ID back to the request.
B11: 3. Assess: in Assessment score Current Maturity 0-5 for each control using Maturity_Model and the L1/L3/L5 anchors in Control_Library. Record tests performed, evidence IDs and notes.
B12: 4. Findings and risks: raise a finding for each material gap in Findings_Register, a matching entry in Risk_Register, and an action in Remediation_Tracker.
B13: 5. Context: capture Crown_Jewels and Attack_Paths so findings are prioritised by business criticality and realistic attack routes.
B14: 6. Report: read results from Dashboard, then complete the Word executive report template.
... B34: Registers are formatted for 200 rows; Assessment and dashboard formulas read to row 2000 so the library can grow to its full size.

Sheet Scope
A1: Engagement Scope
A2: Blue cells on yellow are inputs. Domain and platform choices pre-fill the "Applicable?" column in the Assessment sheet.
B3: Engagement | E3: Default target by tier
B4: Client name | E4: Org tier | F4: Default target
B5: Engagement reference | E5: SMB | F5: 2
B6: Assessment start date | E6: Mid-size | F6: 3
B7: Assessment end date | E7: Enterprise | F7: 3
B8: Lead assessor | E8: Multinational | F8: 4
B9: Reviewer | E9: Government | F9: 4
B10: Organisation size tier | E10: SAOS defaults - edit to client risk appetite.
B11: Industry
B12: Regulatory and contractual drivers
B13: Default target maturity | C13: =IFERROR(INDEX($F$5:$F$9,MATCH(C10,$E$5:$E$9,0)),3) -> 3
B14: Default comes from the tier table; overtype C13 to set a client-specific target. Individual targets can be overtyped in Assessment column L.
B16: Platform scope
B17: Platform | C17: In scope? | G17: Notes
B18: Windows | C18: Yes | G18: Windows Server
B19: Linux | C19: Yes | G19: Linux servers
B20: Hypervisor | C20: Yes | G20: VMware, Hyper-V, Proxmox
B22: Domain scope
B23: Domain | C23: In scope? | G23: Notes
B24: Governance | C24: Yes
B25: Asset Management | C25: Yes
B26: Identity and Access Management | C26: Yes
B27: Endpoint Security | C27: Yes
B28: Server Security | C28: Yes
B29: Network Security | C29: Yes
B30: Microsoft 365 | C30: Yes
B31: Cloud Security | C31: Yes
B32: Application Security | C32: Yes
B33: API Security | C33: Yes
B34: Security Operations | C34: Yes
B35: Vulnerability Management | C35: Yes
... B41: AI Systems (future) | C41: Yes

Sheet Dashboard
B1: SAOS Executive Dashboard
B2: ="Client: "&IF(Scope!C4="","(not set)",Scope!C4)&" | Assessment period: "&IF(Scope!C6="","(not set)",TEXT(Scope!C6,"yyyy-mm-dd"))&" to "&IF(Scope!C7="","(not set)",TEXT(Scope!C7,"yyyy-mm-dd")) -> Client: (not set) | Assessment period: (not set) to (not set)
B4: Overall maturity (0-5) | C4: Maturity % | E4: Assessment completion | G4: Controls with a gap | I4: Critical / High residual | K4: Open Critical/High findings
B5: =IFERROR(SUMPRODUCT((Assessment!$J$5:$J$2000="Yes")*ISNUMBER(Assessment!$K$5:$K$2000)*Assessment!$G$5:$G$2000*Assessment!$K$5:$K$2000)/SUMPRODUCT((Assessment!$J$5:$J$2000="Yes")*ISNUMBER(Assessment!$K$5:$K$2000)*Assessment!$G$5:$G$2000),"n/a") -> n/a | C5: =IFERROR(SUMPRODUCT((Assessment!$J$5:$J$2000="Yes")*ISNUMBER(Assessment!$K$5:$K$2000)*Assessment!$G$5:$G$2000*Assessment!$K$5:$K$2000)/SUMPRODUCT((Assessment!$J$5:$J$2000="Yes")*ISNUMBER(Assessment!$K$5:$K$2000)*Assessment!$G$5:$G$2000)/5,"n/a") -> n/a | E5: =IFERROR(COUNTIFS(Assessment!$J$5:$J$2000,"Yes",Assessment!$K$5:$K$2000,">=0")/COUNTIF(Assessment!$J$5:$J$2000,"Yes"),0) -> 0 | G5: =COUNTIF(Assessment!$N$5:$N$2000,"Gap") -> 0 | I5: =COUNTIF(Assessment!$Z$5:$Z$2000,"Critical")+COUNTIF(Assessment!$Z$5:$Z$2000,"High") -> 0 | K5: =COUNTIFS(Findings_Register!$F$6:$F$205,"Critical",Findings_Register!$K$6:$K$205,"Open")+COUNTIFS(Findings_Register!$F$6:$F$205,"Critical",Findings_Register!$K$6:$K$205,"In Progress")+COUNTIFS(Findings_Register!$F$6:$F$205,"High",Findings_Register!$K$6:$K$205,"Open")+COUNTIFS(Findings_Register!$F$6:$F$205,"High",Findings_Register!$K$6:$K$205,"In Progress") -> 0
B7: Domain scores
B8: Domain | C8: Controls in library | D8: In scope | E8: Assessed | F8: Avg maturity | G8: Avg target | H8: Gap | I8: Status
B9: Governance | C9: =COUNTIF(Control_Library!$B$5:$B$3000,B9) -> 0 | D9: =COUNTIFS(Assessment!$B$5:$B$2000,B9,Assessment!$J$5:$J$2000,"Yes") -> 0 | E9: =COUNTIFS(Assessment!$B$5:$B$2000,$B9,Assessment!$J$5:$J$2000,"Yes",Assessment!$K$5:$K$2000,">=0") -> 0 | F9: =IF(E9=0,"-",SUMPRODUCT((Assessment!$B$5:$B$2000=$B9)*(Assessment!$J$5:$J$2000="Yes")*ISNUMBER(Assessment!$K$5:$K$2000)*Assessment!$G$5:$G$2000*Assessment!$K$5:$K$2000)/SUMPRODUCT((Assessment!$B$5:$B$2000=$B9)*(Assessment!$J$5:$J$2000="Yes")*ISNUMBER(Assessment!$K$5:$K$2000)*Assessment!$G$5:$G$2000)) -> - | G9: =IF(E9=0,"-",SUMPRODUCT((Assessment!$B$5:$B$2000=$B9)*(Assessment!$J$5:$J$2000="Yes")*ISNUMBER(Assessment!$K$5:$K$2000)*Assessment!$G$5:$G$2000*Assessment!$L$5:$L$2000)/SUMPRODUCT((Assessment!$B$5:$B$2000=$B9)*(Assessment!$J$5:$J$2000="Yes")*ISNUMBER(Assessment!$K$5:$K$2000)*Assessment!$G$5:$G$2000)) -> - | H9: =IF(E9=0,"-",MAX(0,G9-F9)) -> - | I9: =IF(E9=0,"Not assessed",IF(H9<=0,"On target",IF(H9<=1,"Minor gap","Significant gap"))) -> Not assessed
B10: Asset Management | C10: =COUNTIF(Control_Library!$B$5:$B$3000,B10) -> 0 | D10: =COUNTIFS(Assessment!$B$5:$B$2000,B10,Assessment!$J$5:$J$2000,"Yes") -> 0 | E10: =COUNTIFS(Assessment!$B$5:$B$2000,$B10,Assessment!$J$5:$J$2000,"Yes",Assessment!$K$5:$K$2000,">=0") -> 0 | F10: =IF(E10=0,"-",SUMPRODUCT((Assessment!$B$5:$B$2000=$B10)*(Assessment!$J$5:$J$2000="Yes")*ISNUMBER(Assessment!$K$5:$K$2000)*Assessment!$G$5:$G$2000*Assessment!$K$5:$K$2000)/SUMPRODUCT((Assessment!$B$5:$B$2000=$B10)*(Assessment!$J$5:$J$2000="Yes")*ISNUMBER(Assessment!$K$5:$K$2000)*Assessment!$G$5:$G$2000)) -> - | G10: =IF(E10=0,"-",SUMPRODUCT((Assessment!$B$5:$B$2000=$B10)*(Assessment!$J$5:$J$2000="Yes")*ISNUMBER(Assessment!$K$5:$K$2000)*Assessment!$G$5:$G$2000*Assessment!$L$5:$L$2000)/SUMPRODUCT((Assessment!$B$5:$B$2000=$B10)*(Assessment!$J$5:$J$2000="Yes")*ISNUMBER(Assessment!$K$5:$K$2000)*Assessment!$G$5:$G$2000)) -> - | H10: =IF(E10=0,"-",MAX(0,G10-F10)) -> - | I10: =IF(E10=0,"Not assessed",IF(H10<=0,"On target",IF(H10<=1,"Minor gap","Significant gap"))) -> Not assessed
B11: Identity and Access Management | C11: =COUNTIF(Control_Library!$B$5:$B$3000,B11) -> 0 | D11: =COUNTIFS(Assessment!$B$5:$B$2000,B11,Assessment!$J$5:$J$2000,"Yes") -> 0 | E11: =COUNTIFS(Assessment!$B$5:$B$2000,$B11,Assessment!$J$5:$J$2000,"Yes",Assessment!$K$5:$K$2000,">=0") -> 0 | F11: =IF(E11=0,"-",SUMPRODUCT((Assessment!$B$5:$B$2000=$B11)*(Assessment!$J$5:$J$2000="Yes")*ISNUMBER(Assessment!$K$5:$K$2000)*Assessment!$G$5:$G$2000*Assessment!$K$5:$K$2000)/SUMPRODUCT((Assessment!$B$5:$B$2000=$B11)*(Assessment!$J$5:$J$2000="Yes")*ISNUMBER(Assessment!$K$5:$K$2000)*Assessment!$G$5:$G$2000)) -> - | G11: =IF(E11=0,"-",SUMPRODUCT((Assessment!$B$5:$B$2000=$B11)*(Assessment!$J$5:$J$2000="Yes")*ISNUMBER(Assessment!$K$5:$K$2000)*Assessment!$G$5:$G$2000*Assessment!$L$5:$L$2000)/SUMPRODUCT((Assessment!$B$5:$B$2000=$B11)*(Assessment!$J$5:$J$2000="Yes")*ISNUMBER(Assessment!$K$5:$K$2000)*Assessment!$G$5:$G$2000)) -> - | H11: =IF(E11=0,"-",MAX(0,G11-F11)) -> - | I11: =IF(E11=0,"Not assessed",IF(H11<=0,"On target",IF(H11<=1,"Minor gap","Significant gap"))) -> Not assessed
B12: Endpoint Security | C12: =COUNTIF(Control_Library!$B$5:$B$3000,B12) -> 0 | D12: =COUNTIFS(Assessment!$B$5:$B$2000,B12,Assessment!$J$5:$J$2000,"Yes") -> 0 | E12: =COUNTIFS(Assessment!$B$5:$B$2000,$B12,Assessment!$J$5:$J$2000,"Yes",Assessment!$K$5:$K$2000,">=0") -> 0 | F12: =IF(E12=0,"-",SUMPRODUCT((Assessment!$B$5:$B$2000=$B12)*(Assessment!$J$5:$J$2000="Yes")*ISNUMBER(Assessment!$K$5:$K$2000)*Assessment!$G$5:$G$2000*Assessment!$K$5:$K$2000)/SUMPRODUCT((Assessment!$B$5:$B$2000=$B12)*(Assessment!$J$5:$J$2000="Yes")*ISNUMBER(Assessment!$K$5:$K$2000)*Assessment!$G$5:$G$2000)) -> - | G12: =IF(E12=0,"-",SUMPRODUCT((Assessment!$B$5:$B$2000=$B12)*(Assessment!$J$5:$J$2000="Yes")*ISNUMBER(Assessment!$K$5:$K$2000)*Assessment!$G$5:$G$2000*Assessment!$L$5:$L$2000)/SUMPRODUCT((Assessment!$B$5:$B$2000=$B12)*(Assessment!$J$5:$J$2000="Yes")*ISNUMBER(Assessment!$K$5:$K$2000)*Assessment!$G$5:$G$2000)) -> - | H12: =IF(E12=0,"-",MAX(0,G12-F12)) -> - | I12: =IF(E12=0,"Not assessed",IF(H12<=0,"On target",IF(H12<=1,"Minor gap","Significant gap"))) -> Not assessed
B13: Server Security | C13: =COUNTIF(Control_Library!$B$5:$B$3000,B13) -> 60 | D13: =COUNTIFS(Assessment!$B$5:$B$2000,B13,Assessment!$J$5:$J$2000,"Yes") -> 60 | E13: =COUNTIFS(Assessment!$B$5:$B$2000,$B13,Assessment!$J$5:$J$2000,"Yes",Assessment!$K$5:$K$2000,">=0") -> 0 | F13: =IF(E13=0,"-",SUMPRODUCT((Assessment!$B$5:$B$2000=$B13)*(Assessment!$J$5:$J$2000="Yes")*ISNUMBER(Assessment!$K$5:$K$2000)*Assessment!$G$5:$G$2000*Assessment!$K$5:$K$2000)/SUMPRODUCT((Assessment!$B$5:$B$2000=$B13)*(Assessment!$J$5:$J$2000="Yes")*ISNUMBER(Assessment!$K$5:$K$2000)*Assessment!$G$5:$G$2000)) -> - | G13: =IF(E13=0,"-",SUMPRODUCT((Assessment!$B$5:$B$2000=$B13)*(Assessment!$J$5:$J$2000="Yes")*ISNUMBER(Assessment!$K$5:$K$2000)*Assessment!$G$5:$G$2000*Assessment!$L$5:$L$2000)/SUMPRODUCT((Assessment!$B$5:$B$2000=$B13)*(Assessment!$J$5:$J$2000="Yes")*ISNUMBER(Assessment!$K$5:$K$2000)*Assessment!$G$5:$G$2000)) -> - | H13: =IF(E13=0,"-",MAX(0,G13-F13)) -> - | I13: =IF(E13=0,"Not assessed",IF(H13<=0,"On target",IF(H13<=1,"Minor gap","Significant gap"))) -> Not assessed
B14: Network Security | C14: =COUNTIF(Control_Library!$B$5:$B$3000,B14) -> 0 | D14: =COUNTIFS(Assessment!$B$5:$B$2000,B14,Assessment!$J$5:$J$2000,"Yes") -> 0 | E14: =COUNTIFS(Assessment!$B$5:$B$2000,$B14,Assessment!$J$5:$J$2000,"Yes",Assessment!$K$5:$K$2000,">=0") -> 0 | F14: =IF(E14=0,"-",SUMPRODUCT((Assessment!$B$5:$B$2000=$B14)*(Assessment!$J$5:$J$2000="Yes")*ISNUMBER(Assessment!$K$5:$K$2000)*Assessment!$G$5:$G$2000*Assessment!$K$5:$K$2000)/SUMPRODUCT((Assessment!$B$5:$B$2000=$B14)*(Assessment!$J$5:$J$2000="Yes")*ISNUMBER(Assessment!$K$5:$K$2000)*Assessment!$G$5:$G$2000)) -> - | G14: =IF(E14=0,"-",SUMPRODUCT((Assessment!$B$5:$B$2000=$B14)*(Assessment!$J$5:$J$2000="Yes")*ISNUMBER(Assessment!$K$5:$K$2000)*Assessment!$G$5:$G$2000*Assessment!$L$5:$L$2000)/SUMPRODUCT((Assessment!$B$5:$B$2000=$B14)*(Assessment!$J$5:$J$2000="Yes")*ISNUMBER(Assessment!$K$5:$K$2000)*Assessment!$G$5:$G$2000)) -> - | H14: =IF(E14=0,"-",MAX(0,G14-F14)) -> - | I14: =IF(E14=0,"Not assessed",IF(H14<=0,"On target",IF(H14<=1,"Minor gap","Significant gap"))) -> Not assessed
B15: Microsoft 365 | C15: =COUNTIF(Control_Library!$B$5:$B$3000,B15) -> 0 | D15: =COUNTIFS(Assessment!$B$5:$B$2000,B15,Assessment!$J$5:$J$2000,"Yes") -> 0 | E15: =COUNTIFS(Assessment!$B$5:$B$2000,$B15,Assessment!$J$5:$J$2000,"Yes",Assessment!$K$5:$K$2000,">=0") -> 0 | F15: =IF(E15=0,"-",SUMPRODUCT((Assessment!$B$5:$B$2000=$B15)*(Assessment!$J$5:$J$2000="Yes")*ISNUMBER(Assessment!$K$5:$K$2000)*Assessment!$G$5:$G$2000*Assessment!$K$5:$K$2000)/SUMPRODUCT((Assessment!$B$5:$B$2000=$B15)*(Assessment!$J$5:$J$2000="Yes")*ISNUMBER(Assessment!$K$5:$K$2000)*Assessment!$G$5:$G$2000)) -> - | G15: =IF(E15=0,"-",SUMPRODUCT((Assessment!$B$5:$B$2000=$B15)*(Assessment!$J$5:$J$2000="Yes")*ISNUMBER(Assessment!$K$5:$K$2000)*Assessment!$G$5:$G$2000*Assessment!$L$5:$L$2000)/SUMPRODUCT((Assessment!$B$5:$B$2000=$B15)*(Assessment!$J$5:$J$2000="Yes")*ISNUMBER(Assessment!$K$5:$K$2000)*Assessment!$G$5:$G$2000)) -> - | H15: =IF(E15=0,"-",MAX(0,G15-F15)) -> - | I15: =IF(E15=0,"Not assessed",IF(H15<=0,"On target",IF(H15<=1,"Minor gap","Significant gap"))) -> Not assessed
B16: Cloud Security | C16: =COUNTIF(Control_Library!$B$5:$B$3000,B16) -> 0 | D16: =COUNTIFS(Assessment!$B$5:$B$2000,B16,Assessment!$J$5:$J$2000,"Yes") -> 0 | E16: =COUNTIFS(Assessment!$B$5:$B$2000,$B16,Assessment!$J$5:$J$2000,"Yes",Assessment!$K$5:$K$2000,">=0") -> 0 | F16: =IF(E16=0,"-",SUMPRODUCT((Assessment!$B$5:$B$2000=$B16)*(Assessment!$J$5:$J$2000="Yes")*ISNUMBER(Assessment!$K$5:$K$2000)*Assessment!$G$5:$G$2000*Assessment!$K$5:$K$2000)/SUMPRODUCT((Assessment!$B$5:$B$2000=$B16)*(Assessment!$J$5:$J$2000="Yes")*ISNUMBER(Assessment!$K$5:$K$2000)*Assessment!$G$5:$G$2000)) -> - | G16: =IF(E16=0,"-",SUMPRODUCT((Assessment!$B$5:$B$2000=$B16)*(Assessment!$J$5:$J$2000="Yes")*ISNUMBER(Assessment!$K$5:$K$2000)*Assessment!$G$5:$G$2000*Assessment!$L$5:$L$2000)/SUMPRODUCT((Assessment!$B$5:$B$2000=$B16)*(Assessment!$J$5:$J$2000="Yes")*ISNUMBER(Assessment!$K$5:$K$2000)*Assessment!$G$5:$G$2000)) -> - | H16: =IF(E16=0,"-",MAX(0,G16-F16)) -> - | I16: =IF(E16=0,"Not assessed",IF(H16<=0,"On target",IF(H16<=1,"Minor gap","Significant gap"))) -> Not assessed
B17: Application Security | C17: =COUNTIF(Control_Library!$B$5:$B$3000,B17) -> 0 | D17: =COUNTIFS(Assessment!$B$5:$B$2000,B17,Assessment!$J$5:$J$2000,"Yes") -> 0 | E17: =COUNTIFS(Assessment!$B$5:$B$2000,$B17,Assessment!$J$5:$J$2000,"Yes",Assessment!$K$5:$K$2000,">=0") -> 0 | F17: =IF(E17=0,"-",SUMPRODUCT((Assessment!$B$5:$B$2000=$B17)*(Assessment!$J$5:$J$2000="Yes")*ISNUMBER(Assessment!$K$5:$K$2000)*Assessment!$G$5:$G$2000*Assessment!$K$5:$K$2000)/SUMPRODUCT((Assessment!$B$5:$B$2000=$B17)*(Assessment!$J$5:$J$2000="Yes")*ISNUMBER(Assessment!$K$5:$K$2000)*Assessment!$G$5:$G$2000)) -> - | G17: =IF(E17=0,"-",SUMPRODUCT((Assessment!$B$5:$B$2000=$B17)*(Assessment!$J$5:$J$2000="Yes")*ISNUMBER(Assessment!$K$5:$K$2000)*Assessment!$G$5:$G$2000*Assessment!$L$5:$L$2000)/SUMPRODUCT((Assessment!$B$5:$B$2000=$B17)*(Assessment!$J$5:$J$2000="Yes")*ISNUMBER(Assessment!$K$5:$K$2000)*Assessment!$G$5:$G$2000)) -> - | H17: =IF(E17=0,"-",MAX(0,G17-F17)) -> - | I17: =IF(E17=0,"Not assessed",IF(H17<=0,"On target",IF(H17<=1,"Minor gap","Significant gap"))) -> Not assessed
B18: API Security | C18: =COUNTIF(Control_Library!$B$5:$B$3000,B18) -> 0 | D18: =COUNTIFS(Assessment!$B$5:$B$2000,B18,Assessment!$J$5:$J$2000,"Yes") -> 0 | E18: =COUNTIFS(Assessment!$B$5:$B$2000,$B18,Assessment!$J$5:$J$2000,"Yes",Assessment!$K$5:$K$2000,">=0") -> 0 | F18: =IF(E18=0,"-",SUMPRODUCT((Assessment!$B$5:$B$2000=$B18)*(Assessment!$J$5:$J$2000="Yes")*ISNUMBER(Assessment!$K$5:$K$2000)*Assessment!$G$5:$G$2000*Assessment!$K$5:$K$2000)/SUMPRODUCT((Assessment!$B$5:$B$2000=$B18)*(Assessment!$J$5:$J$2000="Yes")*ISNUMBER(Assessment!$K$5:$K$2000)*Assessment!$G$5:$G$2000)) -> - | G18: =IF(E18=0,"-",SUMPRODUCT((Assessment!$B$5:$B$2000=$B18)*(Assessment!$J$5:$J$2000="Yes")*ISNUMBER(Assessment!$K$5:$K$2000)*Assessment!$G$5:$G$2000*Assessment!$L$5:$L$2000)/SUMPRODUCT((Assessment!$B$5:$B$2000=$B18)*(Assessment!$J$5:$J$2000="Yes")*ISNUMBER(Assessment!$K$5:$K$2000)*Assessment!$G$5:$G$2000)) -> - | H18: =IF(E18=0,"-",MAX(0,G18-F18)) -> - | I18: =IF(E18=0,"Not assessed",IF(H18<=0,"On target",IF(H18<=1,"Minor gap","Significant gap"))) -> Not assessed
B19: Security Operations | C19: =COUNTIF(Control_Library!$B$5:$B$3000,B19) -> 0 | D19: =COUNTIFS(Assessment!$B$5:$B$2000,B19,Assessment!$J$5:$J$2000,"Yes") -> 0 | E19: =COUNTIFS(Assessment!$B$5:$B$2000,$B19,Assessment!$J$5:$J$2000,"Yes",Assessment!$K$5:$K$2000,">=0") -> 0 | F19: =IF(E19=0,"-",SUMPRODUCT((Assessment!$B$5:$B$2000=$B19)*(Assessment!$J$5:$J$2000="Yes")*ISNUMBER(Assessment!$K$5:$K$2000)*Assessment!$G$5:$G$2000*Assessment!$K$5:$K$2000)/SUMPRODUCT((Assessment!$B$5:$B$2000=$B19)*(Assessment!$J$5:$J$2000="Yes")*ISNUMBER(Assessment!$K$5:$K$2000)*Assessment!$G$5:$G$2000)) -> - | G19: =IF(E19=0,"-",SUMPRODUCT((Assessment!$B$5:$B$2000=$B19)*(Assessment!$J$5:$J$2000="Yes")*ISNUMBER(Assessment!$K$5:$K$2000)*Assessment!$G$5:$G$2000*Assessment!$L$5:$L$2000)/SUMPRODUCT((Assessment!$B$5:$B$2000=$B19)*(Assessment!$J$5:$J$2000="Yes")*ISNUMBER(Assessment!$K$5:$K$2000)*Assessment!$G$5:$G$2000)) -> - | H19: =IF(E19=0,"-",MAX(0,G19-F19)) -> - | I19: =IF(E19=0,"Not assessed",IF(H19<=0,"On target",IF(H19<=1,"Minor gap","Significant gap"))) -> Not assessed
B20: Vulnerability Management | C20: =COUNTIF(Control_Library!$B$5:$B$3000,B20) -> 0 | D20: =COUNTIFS(Assessment!$B$5:$B$2000,B20,Assessment!$J$5:$J$2000,"Yes") -> 0 | E20: =COUNTIFS(Assessment!$B$5:$B$2000,$B20,Assessment!$J$5:$J$2000,"Yes",Assessment!$K$5:$K$2000,">=0") -> 0 | F20: =IF(E20=0,"-",SUMPRODUCT((Assessment!$B$5:$B$2000=$B20)*(Assessment!$J$5:$J$2000="Yes")*ISNUMBER(Assessment!$K$5:$K$2000)*Assessment!$G$5:$G$2000*Assessment!$K$5:$K$2000)/SUMPRODUCT((Assessment!$B$5:$B$2000=$B20)*(Assessment!$J$5:$J$2000="Yes")*ISNUMBER(Assessment!$K$5:$K$2000)*Assessment!$G$5:$G$2000)) -> - | G20: =IF(E20=0,"-",SUMPRODUCT((Assessment!$B$5:$B$2000=$B20)*(Assessment!$J$5:$J$2000="Yes")*ISNUMBER(Assessment!$K$5:$K$2000)*Assessment!$G$5:$G$2000*Assessment!$L$5:$L$2000)/SUMPRODUCT((Assessment!$B$5:$B$2000=$B20)*(Assessment!$J$5:$J$2000="Yes")*ISNUMBER(Assessment!$K$5:$K$2000)*Assessment!$G$5:$G$2000)) -> - | H20: =IF(E20=0,"-",MAX(0,G20-F20)) -> - | I20: =IF(E20=0,"Not assessed",IF(H20<=0,"On target",IF(H20<=1,"Minor gap","Significant gap"))) -> Not assessed
... B26: AI Systems (future) | C26: =COUNTIF(Control_Library!$B$5:$B$3000,B26) -> 0 | D26: =COUNTIFS(Assessment!$B$5:$B$2000,B26,Assessment!$J$5:$J$2000,"Yes") -> 0 | E26: =COUNTIFS(Assessment!$B$5:$B$2000,$B26,Assessment!$J$5:$J$2000,"Yes",Assessment!$K$5:$K$2000,">=0") -> 0 | F26: =IF(E26=0,"-",SUMPRODUCT((Assessment!$B$5:$B$2000=$B26)*(Assessment!$J$5:$J$2000="Yes")*ISNUMBER(Assessment!$K$5:$K$2000)*Assessment!$G$5:$G$2000*Assessment!$K$5:$K$2000)/SUMPRODUCT((Assessment!$B$5:$B$2000=$B26)*(Assessment!$J$5:$J$2000="Yes")*ISNUMBER(Assessment!$K$5:$K$2000)*Assessment!$G$5:$G$2000)) -> - | G26: =IF(E26=0,"-",SUMPRODUCT((Assessment!$B$5:$B$2000=$B26)*(Assessment!$J$5:$J$2000="Yes")*ISNUMBER(Assessment!$K$5:$K$2000)*Assessment!$G$5:$G$2000*Assessment!$L$5:$L$2000)/SUMPRODUCT((Assessment!$B$5:$B$2000=$B26)*(Assessment!$J$5:$J$2000="Yes")*ISNUMBER(Assessment!$K$5:$K$2000)*Assessment!$G$5:$G$2000)) -> - | H26: =IF(E26=0,"-",MAX(0,G26-F26)) -> - | I26: =IF(E26=0,"Not assessed",IF(H26<=0,"On target",IF(H26<=1,"Minor gap","Significant gap"))) -> Not assessed
B28: Control family scores (heat map)
B29: Family | C29: Domain | D29: In scope | E29: Assessed | F29: Avg maturity | G29: Avg target | H29: Gap | I29: Status
B30: Physical and Environmental Security | C30: Server Security | D30: =COUNTIFS(Assessment!$B$5:$B$2000,C30,Assessment!$C$5:$C$2000,B30,Assessment!$J$5:$J$2000,"Yes") -> 4 | E30: =COUNTIFS(Assessment!$B$5:$B$2000,$C30,Assessment!$C$5:$C$2000,$B30,Assessment!$J$5:$J$2000,"Yes",Assessment!$K$5:$K$2000,">=0") -> 0 | F30: =IF(E30=0,"-",SUMPRODUCT((Assessment!$B$5:$B$2000=$C30)*(Assessment!$C$5:$C$2000=$B30)*(Assessment!$J$5:$J$2000="Yes")*ISNUMBER(Assessment!$K$5:$K$2000)*Assessment!$G$5:$G$2000*Assessment!$K$5:$K$2000)/SUMPRODUCT((Assessment!$B$5:$B$2000=$C30)*(Assessment!$C$5:$C$2000=$B30)*(Assessment!$J$5:$J$2000="Yes")*ISNUMBER(Assessment!$K$5:$K$2000)*Assessment!$G$5:$G$2000)) -> - | G30: =IF(E30=0,"-",SUMPRODUCT((Assessment!$B$5:$B$2000=$C30)*(Assessment!$C$5:$C$2000=$B30)*(Assessment!$J$5:$J$2000="Yes")*ISNUMBER(Assessment!$K$5:$K$2000)*Assessment!$G$5:$G$2000*Assessment!$L$5:$L$2000)/SUMPRODUCT((Assessment!$B$5:$B$2000=$C30)*(Assessment!$C$5:$C$2000=$B30)*(Assessment!$J$5:$J$2000="Yes")*ISNUMBER(Assessment!$K$5:$K$2000)*Assessment!$G$5:$G$2000)) -> - | H30: =IF(E30=0,"-",MAX(0,G30-F30)) -> - | I30: =IF(E30=0,"Not assessed",IF(H30<=0,"On target",IF(H30<=1,"Minor gap","Significant gap"))) -> Not assessed
B31: Secure Configuration and Change | C31: Server Security | D31: =COUNTIFS(Assessment!$B$5:$B$2000,C31,Assessment!$C$5:$C$2000,B31,Assessment!$J$5:$J$2000,"Yes") -> 7 | E31: =COUNTIFS(Assessment!$B$5:$B$2000,$C31,Assessment!$C$5:$C$2000,$B31,Assessment!$J$5:$J$2000,"Yes",Assessment!$K$5:$K$2000,">=0") -> 0 | F31: =IF(E31=0,"-",SUMPRODUCT((Assessment!$B$5:$B$2000=$C31)*(Assessment!$C$5:$C$2000=$B31)*(Assessment!$J$5:$J$2000="Yes")*ISNUMBER(Assessment!$K$5:$K$2000)*Assessment!$G$5:$G$2000*Assessment!$K$5:$K$2000)/SUMPRODUCT((Assessment!$B$5:$B$2000=$C31)*(Assessment!$C$5:$C$2000=$B31)*(Assessment!$J$5:$J$2000="Yes")*ISNUMBER(Assessment!$K$5:$K$2000)*Assessment!$G$5:$G$2000)) -> - | G31: =IF(E31=0,"-",SUMPRODUCT((Assessment!$B$5:$B$2000=$C31)*(Assessment!$C$5:$C$2000=$B31)*(Assessment!$J$5:$J$2000="Yes")*ISNUMBER(Assessment!$K$5:$K$2000)*Assessment!$G$5:$G$2000*Assessment!$L$5:$L$2000)/SUMPRODUCT((Assessment!$B$5:$B$2000=$C31)*(Assessment!$C$5:$C$2000=$B31)*(Assessment!$J$5:$J$2000="Yes")*ISNUMBER(Assessment!$K$5:$K$2000)*Assessment!$G$5:$G$2000)) -> - | H31: =IF(E31=0,"-",MAX(0,G31-F31)) -> - | I31: =IF(E31=0,"Not assessed",IF(H31<=0,"On target",IF(H31<=1,"Minor gap","Significant gap"))) -> Not assessed
B32: Patch and Lifecycle Management | C32: Server Security | D32: =COUNTIFS(Assessment!$B$5:$B$2000,C32,Assessment!$C$5:$C$2000,B32,Assessment!$J$5:$J$2000,"Yes") -> 5 | E32: =COUNTIFS(Assessment!$B$5:$B$2000,$C32,Assessment!$C$5:$C$2000,$B32,Assessment!$J$5:$J$2000,"Yes",Assessment!$K$5:$K$2000,">=0") -> 0 | F32: =IF(E32=0,"-",SUMPRODUCT((Assessment!$B$5:$B$2000=$C32)*(Assessment!$C$5:$C$2000=$B32)*(Assessment!$J$5:$J$2000="Yes")*ISNUMBER(Assessment!$K$5:$K$2000)*Assessment!$G$5:$G$2000*Assessment!$K$5:$K$2000)/SUMPRODUCT((Assessment!$B$5:$B$2000=$C32)*(Assessment!$C$5:$C$2000=$B32)*(Assessment!$J$5:$J$2000="Yes")*ISNUMBER(Assessment!$K$5:$K$2000)*Assessment!$G$5:$G$2000)) -> - | G32: =IF(E32=0,"-",SUMPRODUCT((Assessment!$B$5:$B$2000=$C32)*(Assessment!$C$5:$C$2000=$B32)*(Assessment!$J$5:$J$2000="Yes")*ISNUMBER(Assessment!$K$5:$K$2000)*Assessment!$G$5:$G$2000*Assessment!$L$5:$L$2000)/SUMPRODUCT((Assessment!$B$5:$B$2000=$C32)*(Assessment!$C$5:$C$2000=$B32)*(Assessment!$J$5:$J$2000="Yes")*ISNUMBER(Assessment!$K$5:$K$2000)*Assessment!$G$5:$G$2000)) -> - | H32: =IF(E32=0,"-",MAX(0,G32-F32)) -> - | I32: =IF(E32=0,"Not assessed",IF(H32<=0,"On target",IF(H32<=1,"Minor gap","Significant gap"))) -> Not assessed
B33: Logging and Time Synchronization | C33: Server Security | D33: =COUNTIFS(Assessment!$B$5:$B$2000,C33,Assessment!$C$5:$C$2000,B33,Assessment!$J$5:$J$2000,"Yes") -> 6 | E33: =COUNTIFS(Assessment!$B$5:$B$2000,$C33,Assessment!$C$5:$C$2000,$B33,Assessment!$J$5:$J$2000,"Yes",Assessment!$K$5:$K$2000,">=0") -> 0 | F33: =IF(E33=0,"-",SUMPRODUCT((Assessment!$B$5:$B$2000=$C33)*(Assessment!$C$5:$C$2000=$B33)*(Assessment!$J$5:$J$2000="Yes")*ISNUMBER(Assessment!$K$5:$K$2000)*Assessment!$G$5:$G$2000*Assessment!$K$5:$K$2000)/SUMPRODUCT((Assessment!$B$5:$B$2000=$C33)*(Assessment!$C$5:$C$2000=$B33)*(Assessment!$J$5:$J$2000="Yes")*ISNUMBER(Assessment!$K$5:$K$2000)*Assessment!$G$5:$G$2000)) -> - | G33: =IF(E33=0,"-",SUMPRODUCT((Assessment!$B$5:$B$2000=$C33)*(Assessment!$C$5:$C$2000=$B33)*(Assessment!$J$5:$J$2000="Yes")*ISNUMBER(Assessment!$K$5:$K$2000)*Assessment!$G$5:$G$2000*Assessment!$L$5:$L$2000)/SUMPRODUCT((Assessment!$B$5:$B$2000=$C33)*(Assessment!$C$5:$C$2000=$B33)*(Assessment!$J$5:$J$2000="Yes")*ISNUMBER(Assessment!$K$5:$K$2000)*Assessment!$G$5:$G$2000)) -> - | H33: =IF(E33=0,"-",MAX(0,G33-F33)) -> - | I33: =IF(E33=0,"Not assessed",IF(H33<=0,"On target",IF(H33<=1,"Minor gap","Significant gap"))) -> Not assessed
B34: Host Protection | C34: Server Security | D34: =COUNTIFS(Assessment!$B$5:$B$2000,C34,Assessment!$C$5:$C$2000,B34,Assessment!$J$5:$J$2000,"Yes") -> 4 | E34: =COUNTIFS(Assessment!$B$5:$B$2000,$C34,Assessment!$C$5:$C$2000,$B34,Assessment!$J$5:$J$2000,"Yes",Assessment!$K$5:$K$2000,">=0") -> 0 | F34: =IF(E34=0,"-",SUMPRODUCT((Assessment!$B$5:$B$2000=$C34)*(Assessment!$C$5:$C$2000=$B34)*(Assessment!$J$5:$J$2000="Yes")*ISNUMBER(Assessment!$K$5:$K$2000)*Assessment!$G$5:$G$2000*Assessment!$K$5:$K$2000)/SUMPRODUCT((Assessment!$B$5:$B$2000=$C34)*(Assessment!$C$5:$C$2000=$B34)*(Assessment!$J$5:$J$2000="Yes")*ISNUMBER(Assessment!$K$5:$K$2000)*Assessment!$G$5:$G$2000)) -> - | G34: =IF(E34=0,"-",SUMPRODUCT((Assessment!$B$5:$B$2000=$C34)*(Assessment!$C$5:$C$2000=$B34)*(Assessment!$J$5:$J$2000="Yes")*ISNUMBER(Assessment!$K$5:$K$2000)*Assessment!$G$5:$G$2000*Assessment!$L$5:$L$2000)/SUMPRODUCT((Assessment!$B$5:$B$2000=$C34)*(Assessment!$C$5:$C$2000=$B34)*(Assessment!$J$5:$J$2000="Yes")*ISNUMBER(Assessment!$K$5:$K$2000)*Assessment!$G$5:$G$2000)) -> - | H34: =IF(E34=0,"-",MAX(0,G34-F34)) -> - | I34: =IF(E34=0,"Not assessed",IF(H34<=0,"On target",IF(H34<=1,"Minor gap","Significant gap"))) -> Not assessed
B35: Vulnerability Assessment | C35: Server Security | D35: =COUNTIFS(Assessment!$B$5:$B$2000,C35,Assessment!$C$5:$C$2000,B35,Assessment!$J$5:$J$2000,"Yes") -> 4 | E35: =COUNTIFS(Assessment!$B$5:$B$2000,$C35,Assessment!$C$5:$C$2000,$B35,Assessment!$J$5:$J$2000,"Yes",Assessment!$K$5:$K$2000,">=0") -> 0 | F35: =IF(E35=0,"-",SUMPRODUCT((Assessment!$B$5:$B$2000=$C35)*(Assessment!$C$5:$C$2000=$B35)*(Assessment!$J$5:$J$2000="Yes")*ISNUMBER(Assessment!$K$5:$K$2000)*Assessment!$G$5:$G$2000*Assessment!$K$5:$K$2000)/SUMPRODUCT((Assessment!$B$5:$B$2000=$C35)*(Assessment!$C$5:$C$2000=$B35)*(Assessment!$J$5:$J$2000="Yes")*ISNUMBER(Assessment!$K$5:$K$2000)*Assessment!$G$5:$G$2000)) -> - | G35: =IF(E35=0,"-",SUMPRODUCT((Assessment!$B$5:$B$2000=$C35)*(Assessment!$C$5:$C$2000=$B35)*(Assessment!$J$5:$J$2000="Yes")*ISNUMBER(Assessment!$K$5:$K$2000)*Assessment!$G$5:$G$2000*Assessment!$L$5:$L$2000)/SUMPRODUCT((Assessment!$B$5:$B$2000=$C35)*(Assessment!$C$5:$C$2000=$B35)*(Assessment!$J$5:$J$2000="Yes")*ISNUMBER(Assessment!$K$5:$K$2000)*Assessment!$G$5:$G$2000)) -> - | H35: =IF(E35=0,"-",MAX(0,G35-F35)) -> - | I35: =IF(E35=0,"Not assessed",IF(H35<=0,"On target",IF(H35<=1,"Minor gap","Significant gap"))) -> Not assessed
B36: Network Placement and Exposure | C36: Server Security | D36: =COUNTIFS(Assessment!$B$5:$B$2000,C36,Assessment!$C$5:$C$2000,B36,Assessment!$J$5:$J$2000,"Yes") -> 1 | E36: =COUNTIFS(Assessment!$B$5:$B$2000,$C36,Assessment!$C$5:$C$2000,$B36,Assessment!$J$5:$J$2000,"Yes",Assessment!$K$5:$K$2000,">=0") -> 0 | F36: =IF(E36=0,"-",SUMPRODUCT((Assessment!$B$5:$B$2000=$C36)*(Assessment!$C$5:$C$2000=$B36)*(Assessment!$J$5:$J$2000="Yes")*ISNUMBER(Assessment!$K$5:$K$2000)*Assessment!$G$5:$G$2000*Assessment!$K$5:$K$2000)/SUMPRODUCT((Assessment!$B$5:$B$2000=$C36)*(Assessment!$C$5:$C$2000=$B36)*(Assessment!$J$5:$J$2000="Yes")*ISNUMBER(Assessment!$K$5:$K$2000)*Assessment!$G$5:$G$2000)) -> - | G36: =IF(E36=0,"-",SUMPRODUCT((Assessment!$B$5:$B$2000=$C36)*(Assessment!$C$5:$C$2000=$B36)*(Assessment!$J$5:$J$2000="Yes")*ISNUMBER(Assessment!$K$5:$K$2000)*Assessment!$G$5:$G$2000*Assessment!$L$5:$L$2000)/SUMPRODUCT((Assessment!$B$5:$B$2000=$C36)*(Assessment!$C$5:$C$2000=$B36)*(Assessment!$J$5:$J$2000="Yes")*ISNUMBER(Assessment!$K$5:$K$2000)*Assessment!$G$5:$G$2000)) -> - | H36: =IF(E36=0,"-",MAX(0,G36-F36)) -> - | I36: =IF(E36=0,"Not assessed",IF(H36<=0,"On target",IF(H36<=1,"Minor gap","Significant gap"))) -> Not assessed
B37: Authentication and Access Control | C37: Server Security | D37: =COUNTIFS(Assessment!$B$5:$B$2000,C37,Assessment!$C$5:$C$2000,B37,Assessment!$J$5:$J$2000,"Yes") -> 9 | E37: =COUNTIFS(Assessment!$B$5:$B$2000,$C37,Assessment!$C$5:$C$2000,$B37,Assessment!$J$5:$J$2000,"Yes",Assessment!$K$5:$K$2000,">=0") -> 0 | F37: =IF(E37=0,"-",SUMPRODUCT((Assessment!$B$5:$B$2000=$C37)*(Assessment!$C$5:$C$2000=$B37)*(Assessment!$J$5:$J$2000="Yes")*ISNUMBER(Assessment!$K$5:$K$2000)*Assessment!$G$5:$G$2000*Assessment!$K$5:$K$2000)/SUMPRODUCT((Assessment!$B$5:$B$2000=$C37)*(Assessment!$C$5:$C$2000=$B37)*(Assessment!$J$5:$J$2000="Yes")*ISNUMBER(Assessment!$K$5:$K$2000)*Assessment!$G$5:$G$2000)) -> - | G37: =IF(E37=0,"-",SUMPRODUCT((Assessment!$B$5:$B$2000=$C37)*(Assessment!$C$5:$C$2000=$B37)*(Assessment!$J$5:$J$2000="Yes")*ISNUMBER(Assessment!$K$5:$K$2000)*Assessment!$G$5:$G$2000*Assessment!$L$5:$L$2000)/SUMPRODUCT((Assessment!$B$5:$B$2000=$C37)*(Assessment!$C$5:$C$2000=$B37)*(Assessment!$J$5:$J$2000="Yes")*ISNUMBER(Assessment!$K$5:$K$2000)*Assessment!$G$5:$G$2000)) -> - | H37: =IF(E37=0,"-",MAX(0,G37-F37)) -> - | I37: =IF(E37=0,"Not assessed",IF(H37<=0,"On target",IF(H37<=1,"Minor gap","Significant gap"))) -> Not assessed
B38: Secure Administration | C38: Server Security | D38: =COUNTIFS(Assessment!$B$5:$B$2000,C38,Assessment!$C$5:$C$2000,B38,Assessment!$J$5:$J$2000,"Yes") -> 2 | E38: =COUNTIFS(Assessment!$B$5:$B$2000,$C38,Assessment!$C$5:$C$2000,$B38,Assessment!$J$5:$J$2000,"Yes",Assessment!$K$5:$K$2000,">=0") -> 0 | F38: =IF(E38=0,"-",SUMPRODUCT((Assessment!$B$5:$B$2000=$C38)*(Assessment!$C$5:$C$2000=$B38)*(Assessment!$J$5:$J$2000="Yes")*ISNUMBER(Assessment!$K$5:$K$2000)*Assessment!$G$5:$G$2000*Assessment!$K$5:$K$2000)/SUMPRODUCT((Assessment!$B$5:$B$2000=$C38)*(Assessment!$C$5:$C$2000=$B38)*(Assessment!$J$5:$J$2000="Yes")*ISNUMBER(Assessment!$K$5:$K$2000)*Assessment!$G$5:$G$2000)) -> - | G38: =IF(E38=0,"-",SUMPRODUCT((Assessment!$B$5:$B$2000=$C38)*(Assessment!$C$5:$C$2000=$B38)*(Assessment!$J$5:$J$2000="Yes")*ISNUMBER(Assessment!$K$5:$K$2000)*Assessment!$G$5:$G$2000*Assessment!$L$5:$L$2000)/SUMPRODUCT((Assessment!$B$5:$B$2000=$C38)*(Assessment!$C$5:$C$2000=$B38)*(Assessment!$J$5:$J$2000="Yes")*ISNUMBER(Assessment!$K$5:$K$2000)*Assessment!$G$5:$G$2000)) -> - | H38: =IF(E38=0,"-",MAX(0,G38-F38)) -> - | I38: =IF(E38=0,"Not assessed",IF(H38<=0,"On target",IF(H38<=1,"Minor gap","Significant gap"))) -> Not assessed
B39: Backup, Restore and Recovery | C39: Server Security | D39: =COUNTIFS(Assessment!$B$5:$B$2000,C39,Assessment!$C$5:$C$2000,B39,Assessment!$J$5:$J$2000,"Yes") -> 6 | E39: =COUNTIFS(Assessment!$B$5:$B$2000,$C39,Assessment!$C$5:$C$2000,$B39,Assessment!$J$5:$J$2000,"Yes",Assessment!$K$5:$K$2000,">=0") -> 0 | F39: =IF(E39=0,"-",SUMPRODUCT((Assessment!$B$5:$B$2000=$C39)*(Assessment!$C$5:$C$2000=$B39)*(Assessment!$J$5:$J$2000="Yes")*ISNUMBER(Assessment!$K$5:$K$2000)*Assessment!$G$5:$G$2000*Assessment!$K$5:$K$2000)/SUMPRODUCT((Assessment!$B$5:$B$2000=$C39)*(Assessment!$C$5:$C$2000=$B39)*(Assessment!$J$5:$J$2000="Yes")*ISNUMBER(Assessment!$K$5:$K$2000)*Assessment!$G$5:$G$2000)) -> - | G39: =IF(E39=0,"-",SUMPRODUCT((Assessment!$B$5:$B$2000=$C39)*(Assessment!$C$5:$C$2000=$B39)*(Assessment!$J$5:$J$2000="Yes")*ISNUMBER(Assessment!$K$5:$K$2000)*Assessment!$G$5:$G$2000*Assessment!$L$5:$L$2000)/SUMPRODUCT((Assessment!$B$5:$B$2000=$C39)*(Assessment!$C$5:$C$2000=$B39)*(Assessment!$J$5:$J$2000="Yes")*ISNUMBER(Assessment!$K$5:$K$2000)*Assessment!$G$5:$G$2000)) -> - | H39: =IF(E39=0,"-",MAX(0,G39-F39)) -> - | I39: =IF(E39=0,"Not assessed",IF(H39<=0,"On target",IF(H39<=1,"Minor gap","Significant gap"))) -> Not assessed
B40: Data Protection | C40: Server Security | D40: =COUNTIFS(Assessment!$B$5:$B$2000,C40,Assessment!$C$5:$C$2000,B40,Assessment!$J$5:$J$2000,"Yes") -> 3 | E40: =COUNTIFS(Assessment!$B$5:$B$2000,$C40,Assessment!$C$5:$C$2000,$B40,Assessment!$J$5:$J$2000,"Yes",Assessment!$K$5:$K$2000,">=0") -> 0 | F40: =IF(E40=0,"-",SUMPRODUCT((Assessment!$B$5:$B$2000=$C40)*(Assessment!$C$5:$C$2000=$B40)*(Assessment!$J$5:$J$2000="Yes")*ISNUMBER(Assessment!$K$5:$K$2000)*Assessment!$G$5:$G$2000*Assessment!$K$5:$K$2000)/SUMPRODUCT((Assessment!$B$5:$B$2000=$C40)*(Assessment!$C$5:$C$2000=$B40)*(Assessment!$J$5:$J$2000="Yes")*ISNUMBER(Assessment!$K$5:$K$2000)*Assessment!$G$5:$G$2000)) -> - | G40: =IF(E40=0,"-",SUMPRODUCT((Assessment!$B$5:$B$2000=$C40)*(Assessment!$C$5:$C$2000=$B40)*(Assessment!$J$5:$J$2000="Yes")*ISNUMBER(Assessment!$K$5:$K$2000)*Assessment!$G$5:$G$2000*Assessment!$L$5:$L$2000)/SUMPRODUCT((Assessment!$B$5:$B$2000=$C40)*(Assessment!$C$5:$C$2000=$B40)*(Assessment!$J$5:$J$2000="Yes")*ISNUMBER(Assessment!$K$5:$K$2000)*Assessment!$G$5:$G$2000)) -> - | H40: =IF(E40=0,"-",MAX(0,G40-F40)) -> - | I40: =IF(E40=0,"Not assessed",IF(H40<=0,"On target",IF(H40<=1,"Minor gap","Significant gap"))) -> Not assessed
B41: Governance, Ownership and Risk | C41: Server Security | D41: =COUNTIFS(Assessment!$B$5:$B$2000,C41,Assessment!$C$5:$C$2000,B41,Assessment!$J$5:$J$2000,"Yes") -> 4 | E41: =COUNTIFS(Assessment!$B$5:$B$2000,$C41,Assessment!$C$5:$C$2000,$B41,Assessment!$J$5:$J$2000,"Yes",Assessment!$K$5:$K$2000,">=0") -> 0 | F41: =IF(E41=0,"-",SUMPRODUCT((Assessment!$B$5:$B$2000=$C41)*(Assessment!$C$5:$C$2000=$B41)*(Assessment!$J$5:$J$2000="Yes")*ISNUMBER(Assessment!$K$5:$K$2000)*Assessment!$G$5:$G$2000*Assessment!$K$5:$K$2000)/SUMPRODUCT((Assessment!$B$5:$B$2000=$C41)*(Assessment!$C$5:$C$2000=$B41)*(Assessment!$J$5:$J$2000="Yes")*ISNUMBER(Assessment!$K$5:$K$2000)*Assessment!$G$5:$G$2000)) -> - | G41: =IF(E41=0,"-",SUMPRODUCT((Assessment!$B$5:$B$2000=$C41)*(Assessment!$C$5:$C$2000=$B41)*(Assessment!$J$5:$J$2000="Yes")*ISNUMBER(Assessment!$K$5:$K$2000)*Assessment!$G$5:$G$2000*Assessment!$L$5:$L$2000)/SUMPRODUCT((Assessment!$B$5:$B$2000=$C41)*(Assessment!$C$5:$C$2000=$B41)*(Assessment!$J$5:$J$2000="Yes")*ISNUMBER(Assessment!$K$5:$K$2000)*Assessment!$G$5:$G$2000)) -> - | H41: =IF(E41=0,"-",MAX(0,G41-F41)) -> - | I41: =IF(E41=0,"Not assessed",IF(H41<=0,"On target",IF(H41<=1,"Minor gap","Significant gap"))) -> Not assessed
B42: Virtualization Platforms | C42: Server Security | D42: =COUNTIFS(Assessment!$B$5:$B$2000,C42,Assessment!$C$5:$C$2000,B42,Assessment!$J$5:$J$2000,"Yes") -> 5 | E42: =COUNTIFS(Assessment!$B$5:$B$2000,$C42,Assessment!$C$5:$C$2000,$B42,Assessment!$J$5:$J$2000,"Yes",Assessment!$K$5:$K$2000,">=0") -> 0 | F42: =IF(E42=0,"-",SUMPRODUCT((Assessment!$B$5:$B$2000=$C42)*(Assessment!$C$5:$C$2000=$B42)*(Assessment!$J$5:$J$2000="Yes")*ISNUMBER(Assessment!$K$5:$K$2000)*Assessment!$G$5:$G$2000*Assessment!$K$5:$K$2000)/SUMPRODUCT((Assessment!$B$5:$B$2000=$C42)*(Assessment!$C$5:$C$2000=$B42)*(Assessment!$J$5:$J$2000="Yes")*ISNUMBER(Assessment!$K$5:$K$2000)*Assessment!$G$5:$G$2000)) -> - | G42: =IF(E42=0,"-",SUMPRODUCT((Assessment!$B$5:$B$2000=$C42)*(Assessment!$C$5:$C$2000=$B42)*(Assessment!$J$5:$J$2000="Yes")*ISNUMBER(Assessment!$K$5:$K$2000)*Assessment!$G$5:$G$2000*Assessment!$L$5:$L$2000)/SUMPRODUCT((Assessment!$B$5:$B$2000=$C42)*(Assessment!$C$5:$C$2000=$B42)*(Assessment!$J$5:$J$2000="Yes")*ISNUMBER(Assessment!$K$5:$K$2000)*Assessment!$G$5:$G$2000)) -> - | H42: =IF(E42=0,"-",MAX(0,G42-F42)) -> - | I42: =IF(E42=0,"Not assessed",IF(H42<=0,"On target",IF(H42<=1,"Minor gap","Significant gap"))) -> Not assessed
B44: Maturity distribution (in-scope controls)
B45: Maturity level | C45: Controls
B46: 0 - Non-Existent | C46: =COUNTIFS(Assessment!$J$5:$J$2000,"Yes",Assessment!$K$5:$K$2000,0) -> 0
B47: 1 - Initial | C47: =COUNTIFS(Assessment!$J$5:$J$2000,"Yes",Assessment!$K$5:$K$2000,1) -> 0
B48: 2 - Repeatable | C48: =COUNTIFS(Assessment!$J$5:$J$2000,"Yes",Assessment!$K$5:$K$2000,2) -> 0
B49: 3 - Defined | C49: =COUNTIFS(Assessment!$J$5:$J$2000,"Yes",Assessment!$K$5:$K$2000,3) -> 0
...

Sheet Assessment
A1: Assessment Workbook
A2: Yellow cells with blue text are inputs. Applicable? is pre-filled from Scope (overtype to override). Score 0-5 using Maturity_Model and the anchors in Control_Library.
A4: Control ID | B4: Domain | C4: Control Family | D4: Platform | E4: Control Name | F4: Assessment Question | G4: Weight | H4: Default Likelihood | I4: Default Impact | J4: Applicable? | K4: Current Maturity (0-5) | L4: Target Maturity (0-5) | M4: Gap | N4: Status | O4: Tests Performed | P4: Evidence Ref(s) | Q4: Assessor Notes / Observations | R4: Likelihood Override | S4: Impact Override | T4: Likelihood Used | U4: Impact Used | V4: Inherent Score | W4: Inherent Rating | X4: Control Effectiveness | Y4: Residual Score | Z4: Residual Rating | AA4: Rank Key (helper)
A5: SRV-PHY-01 | B5: Server Security | C5: Physical and Environmental Security | D5: All | E5: Physical access to servers is restricted and logged | F5: Are servers housed in locked racks or access-controlled rooms, with access limited to authorised staff and logged? | G5: 2 | H5: 2 | I5: 5 | J5: =IF(IFERROR(INDEX(Scope!$C$24:$C$41,MATCH($B5,Scope!$B$24:$B$41,0)),"Yes")="No","No",IF($D5="All","Yes",IF(IFERROR(INDEX(Scope!$C$18:$C$20,MATCH($D5,Scope!$B$18:$B$20,0)),"Yes")="No","No","Yes"))) -> Yes | L5: =Scope!$C$13 -> 3 | M5: =IF(AND(J5="Yes",K5<>""),MAX(0,L5-K5),"") | N5: =IF(J5="No","N/A",IF(K5="","Not assessed",IF(K5>=L5,"Meets target","Gap"))) -> Not assessed | T5: =IF(R5<>"",R5,H5) -> 2 | U5: =IF(S5<>"",S5,I5) -> 5 | V5: =T5*U5 -> 10 | W5: =INDEX(Risk_Model!$B$30:$B$33,MATCH(V5,Risk_Model!$A$30:$A$33,1)) -> High | X5: =IF(OR(J5="No",K5=""),"",INDEX(Risk_Model!$C$38:$C$43,MATCH(K5,Risk_Model!$A$38:$A$43,0))) | Y5: =IF(X5="","",ROUND(V5*(1-X5),1)) | Z5: =IF(Y5="","",INDEX(Risk_Model!$B$30:$B$33,MATCH(Y5,Risk_Model!$A$30:$A$33,1))) | AA5: =IF(Y5="","",Y5+ROW()/1000000)
A6: SRV-PHY-02 | B6: Server Security | C6: Physical and Environmental Security | D6: All | E6: Out-of-band management interfaces are isolated and hardened | F6: Are out-of-band management interfaces on a dedicated management network, patched, with default credentials changed and strong authentication enforced? | G6: 3 | H6: 3 | I6: 5 | J6: =IF(IFERROR(INDEX(Scope!$C$24:$C$41,MATCH($B6,Scope!$B$24:$B$41,0)),"Yes")="No","No",IF($D6="All","Yes",IF(IFERROR(INDEX(Scope!$C$18:$C$20,MATCH($D6,Scope!$B$18:$B$20,0)),"Yes")="No","No","Yes"))) -> Yes | L6: =Scope!$C$13 -> 3 | M6: =IF(AND(J6="Yes",K6<>""),MAX(0,L6-K6),"") | N6: =IF(J6="No","N/A",IF(K6="","Not assessed",IF(K6>=L6,"Meets target","Gap"))) -> Not assessed | T6: =IF(R6<>"",R6,H6) -> 3 | U6: =IF(S6<>"",S6,I6) -> 5 | V6: =T6*U6 -> 15 | W6: =INDEX(Risk_Model!$B$30:$B$33,MATCH(V6,Risk_Model!$A$30:$A$33,1)) -> High | X6: =IF(OR(J6="No",K6=""),"",INDEX(Risk_Model!$C$38:$C$43,MATCH(K6,Risk_Model!$A$38:$A$43,0))) | Y6: =IF(X6="","",ROUND(V6*(1-X6),1)) | Z6: =IF(Y6="","",INDEX(Risk_Model!$B$30:$B$33,MATCH(Y6,Risk_Model!$A$30:$A$33,1))) | AA6: =IF(Y6="","",Y6+ROW()/1000000)
A7: SRV-PHY-03 | B7: Server Security | C7: Physical and Environmental Security | D7: All | E7: Removable media and unused ports are controlled | F7: Are USB and removable-media ports, unused console ports and boot-from-removable options disabled or controlled on servers? | G7: 1 | H7: 2 | I7: 4 | J7: =IF(IFERROR(INDEX(Scope!$C$24:$C$41,MATCH($B7,Scope!$B$24:$B$41,0)),"Yes")="No","No",IF($D7="All","Yes",IF(IFERROR(INDEX(Scope!$C$18:$C$20,MATCH($D7,Scope!$B$18:$B$20,0)),"Yes")="No","No","Yes"))) -> Yes | L7: =Scope!$C$13 -> 3 | M7: =IF(AND(J7="Yes",K7<>""),MAX(0,L7-K7),"") | N7: =IF(J7="No","N/A",IF(K7="","Not assessed",IF(K7>=L7,"Meets target","Gap"))) -> Not assessed | T7: =IF(R7<>"",R7,H7) -> 2 | U7: =IF(S7<>"",S7,I7) -> 4 | V7: =T7*U7 -> 8 | W7: =INDEX(Risk_Model!$B$30:$B$33,MATCH(V7,Risk_Model!$A$30:$A$33,1)) -> Medium | X7: =IF(OR(J7="No",K7=""),"",INDEX(Risk_Model!$C$38:$C$43,MATCH(K7,Risk_Model!$A$38:$A$43,0))) | Y7: =IF(X7="","",ROUND(V7*(1-X7),1)) | Z7: =IF(Y7="","",INDEX(Risk_Model!$B$30:$B$33,MATCH(Y7,Risk_Model!$A$30:$A$33,1))) | AA7: =IF(Y7="","",Y7+ROW()/1000000)
A8: SRV-PHY-04 | B8: Server Security | C8: Physical and Environmental Security | D8: All | E8: Storage media is sanitised or destroyed before replacement and disposal | F8: Is media containing confidential data sanitised to a recognised standard or destroyed, with certificates retained, before leaving the organisation or being re-used? | G8: 2 | H8: 2 | I8: 4 | J8: =IF(IFERROR(INDEX(Scope!$C$24:$C$41,MATCH($B8,Scope!$B$24:$B$41,0)),"Yes")="No","No",IF($D8="All","Yes",IF(IFERROR(INDEX(Scope!$C$18:$C$20,MATCH($D8,Scope!$B$18:$B$20,0)),"Yes")="No","No","Yes"))) -> Yes | L8: =Scope!$C$13 -> 3 | M8: =IF(AND(J8="Yes",K8<>""),MAX(0,L8-K8),"") | N8: =IF(J8="No","N/A",IF(K8="","Not assessed",IF(K8>=L8,"Meets target","Gap"))) -> Not assessed | T8: =IF(R8<>"",R8,H8) -> 2 | U8: =IF(S8<>"",S8,I8) -> 4 | V8: =T8*U8 -> 8 | W8: =INDEX(Risk_Model!$B$30:$B$33,MATCH(V8,Risk_Model!$A$30:$A$33,1)) -> Medium | X8: =IF(OR(J8="No",K8=""),"",INDEX(Risk_Model!$C$38:$C$43,MATCH(K8,Risk_Model!$A$38:$A$43,0))) | Y8: =IF(X8="","",ROUND(V8*(1-X8),1)) | Z8: =IF(Y8="","",INDEX(Risk_Model!$B$30:$B$33,MATCH(Y8,Risk_Model!$A$30:$A$33,1))) | AA8: =IF(Y8="","",Y8+ROW()/1000000)
A9: SRV-CFG-01 | B9: Server Security | C9: Secure Configuration and Change | D9: All | E9: Secure configuration baselines are defined for every server platform | F9: Is there an approved hardening baseline (for example CIS Benchmark level) for each server OS and role, and is it applied at build? | G9: 3 | H9: 4 | I9: 4 | J9: =IF(IFERROR(INDEX(Scope!$C$24:$C$41,MATCH($B9,Scope!$B$24:$B$41,0)),"Yes")="No","No",IF($D9="All","Yes",IF(IFERROR(INDEX(Scope!$C$18:$C$20,MATCH($D9,Scope!$B$18:$B$20,0)),"Yes")="No","No","Yes"))) -> Yes | L9: =Scope!$C$13 -> 3 | M9: =IF(AND(J9="Yes",K9<>""),MAX(0,L9-K9),"") | N9: =IF(J9="No","N/A",IF(K9="","Not assessed",IF(K9>=L9,"Meets target","Gap"))) -> Not assessed | T9: =IF(R9<>"",R9,H9) -> 4 | U9: =IF(S9<>"",S9,I9) -> 4 | V9: =T9*U9 -> 16 | W9: =INDEX(Risk_Model!$B$30:$B$33,MATCH(V9,Risk_Model!$A$30:$A$33,1)) -> High | X9: =IF(OR(J9="No",K9=""),"",INDEX(Risk_Model!$C$38:$C$43,MATCH(K9,Risk_Model!$A$38:$A$43,0))) | Y9: =IF(X9="","",ROUND(V9*(1-X9),1)) | Z9: =IF(Y9="","",INDEX(Risk_Model!$B$30:$B$33,MATCH(Y9,Risk_Model!$A$30:$A$33,1))) | AA9: =IF(Y9="","",Y9+ROW()/1000000)
A10: SRV-CFG-02 | B10: Server Security | C10: Secure Configuration and Change | D10: All | E10: Configuration drift from the baseline is detected and corrected | F10: Is compliance with the baseline continuously or periodically assessed, with deviations tracked to closure? | G10: 2 | H10: 3 | I10: 3 | J10: =IF(IFERROR(INDEX(Scope!$C$24:$C$41,MATCH($B10,Scope!$B$24:$B$41,0)),"Yes")="No","No",IF($D10="All","Yes",IF(IFERROR(INDEX(Scope!$C$18:$C$20,MATCH($D10,Scope!$B$18:$B$20,0)),"Yes")="No","No","Yes"))) -> Yes | L10: =Scope!$C$13 -> 3 | M10: =IF(AND(J10="Yes",K10<>""),MAX(0,L10-K10),"") | N10: =IF(J10="No","N/A",IF(K10="","Not assessed",IF(K10>=L10,"Meets target","Gap"))) -> Not assessed | T10: =IF(R10<>"",R10,H10) -> 3 | U10: =IF(S10<>"",S10,I10) -> 3 | V10: =T10*U10 -> 9 | W10: =INDEX(Risk_Model!$B$30:$B$33,MATCH(V10,Risk_Model!$A$30:$A$33,1)) -> Medium | X10: =IF(OR(J10="No",K10=""),"",INDEX(Risk_Model!$C$38:$C$43,MATCH(K10,Risk_Model!$A$38:$A$43,0))) | Y10: =IF(X10="","",ROUND(V10*(1-X10),1)) | Z10: =IF(Y10="","",INDEX(Risk_Model!$B$30:$B$33,MATCH(Y10,Risk_Model!$A$30:$A$33,1))) | AA10: =IF(Y10="","",Y10+ROW()/1000000)
A11: SRV-CFG-03 | B11: Server Security | C11: Secure Configuration and Change | D11: All | E11: Unnecessary services, roles, features and ports are disabled or removed | F11: Are all services, roles, features, protocols and listening ports not required by the server role disabled or removed? | G11: 3 | H11: 3 | I11: 4 | J11: =IF(IFERROR(INDEX(Scope!$C$24:$C$41,MATCH($B11,Scope!$B$24:$B$41,0)),"Yes")="No","No",IF($D11="All","Yes",IF(IFERROR(INDEX(Scope!$C$18:$C$20,MATCH($D11,Scope!$B$18:$B$20,0)),"Yes")="No","No","Yes"))) -> Yes | L11: =Scope!$C$13 -> 3 | M11: =IF(AND(J11="Yes",K11<>""),MAX(0,L11-K11),"") | N11: =IF(J11="No","N/A",IF(K11="","Not assessed",IF(K11>=L11,"Meets target","Gap"))) -> Not assessed | T11: =IF(R11<>"",R11,H11) -> 3 | U11: =IF(S11<>"",S11,I11) -> 4 | V11: =T11*U11 -> 12 | W11: =INDEX(Risk_Model!$B$30:$B$33,MATCH(V11,Risk_Model!$A$30:$A$33,1)) -> High | X11: =IF(OR(J11="No",K11=""),"",INDEX(Risk_Model!$C$38:$C$43,MATCH(K11,Risk_Model!$A$38:$A$43,0))) | Y11: =IF(X11="","",ROUND(V11*(1-X11),1)) | Z11: =IF(Y11="","",INDEX(Risk_Model!$B$30:$B$33,MATCH(Y11,Risk_Model!$A$30:$A$33,1))) | AA11: =IF(Y11="","",Y11+ROW()/1000000)
A12: SRV-CFG-04 | B12: Server Security | C12: Secure Configuration and Change | D12: All | E12: An approved authorised-use banner is displayed at login | F12: Do servers display a legally approved authorised-use notice at console, SSH, RDP and web administration logins? | G12: 1 | H12: 1 | I12: 2 | J12: =IF(IFERROR(INDEX(Scope!$C$24:$C$41,MATCH($B12,Scope!$B$24:$B$41,0)),"Yes")="No","No",IF($D12="All","Yes",IF(IFERROR(INDEX(Scope!$C$18:$C$20,MATCH($D12,Scope!$B$18:$B$20,0)),"Yes")="No","No","Yes"))) -> Yes | L12: =Scope!$C$13 -> 3 | M12: =IF(AND(J12="Yes",K12<>""),MAX(0,L12-K12),"") | N12: =IF(J12="No","N/A",IF(K12="","Not assessed",IF(K12>=L12,"Meets target","Gap"))) -> Not assessed | T12: =IF(R12<>"",R12,H12) -> 1 | U12: =IF(S12<>"",S12,I12) -> 2 | V12: =T12*U12 -> 2 | W12: =INDEX(Risk_Model!$B$30:$B$33,MATCH(V12,Risk_Model!$A$30:$A$33,1)) -> Low | X12: =IF(OR(J12="No",K12=""),"",INDEX(Risk_Model!$C$38:$C$43,MATCH(K12,Risk_Model!$A$38:$A$43,0))) | Y12: =IF(X12="","",ROUND(V12*(1-X12),1)) | Z12: =IF(Y12="","",INDEX(Risk_Model!$B$30:$B$33,MATCH(Y12,Risk_Model!$A$30:$A$33,1))) | AA12: =IF(Y12="","",Y12+ROW()/1000000)
A13: SRV-CFG-05 | B13: Server Security | C13: Secure Configuration and Change | D13: All | E13: Boot chain integrity protections are enabled | F13: Are Secure Boot, a UEFI/BIOS administrator password, TPM-backed measured boot and restricted boot order enabled on physical and virtual servers where supported? | G13: 2 | H13: 2 | I13: 4 | J13: =IF(IFERROR(INDEX(Scope!$C$24:$C$41,MATCH($B13,Scope!$B$24:$B$41,0)),"Yes")="No","No",IF($D13="All","Yes",IF(IFERROR(INDEX(Scope!$C$18:$C$20,MATCH($D13,Scope!$B$18:$B$20,0)),"Yes")="No","No","Yes"))) -> Yes | L13: =Scope!$C$13 -> 3 | M13: =IF(AND(J13="Yes",K13<>""),MAX(0,L13-K13),"") | N13: =IF(J13="No","N/A",IF(K13="","Not assessed",IF(K13>=L13,"Meets target","Gap"))) -> Not assessed | T13: =IF(R13<>"",R13,H13) -> 2 | U13: =IF(S13<>"",S13,I13) -> 4 | V13: =T13*U13 -> 8 | W13: =INDEX(Risk_Model!$B$30:$B$33,MATCH(V13,Risk_Model!$A$30:$A$33,1)) -> Medium | X13: =IF(OR(J13="No",K13=""),"",INDEX(Risk_Model!$C$38:$C$43,MATCH(K13,Risk_Model!$A$38:$A$43,0))) | Y13: =IF(X13="","",ROUND(V13*(1-X13),1)) | Z13: =IF(Y13="","",INDEX(Risk_Model!$B$30:$B$33,MATCH(Y13,Risk_Model!$A$30:$A$33,1))) | AA13: =IF(Y13="","",Y13+ROW()/1000000)
A14: SRV-CFG-06 | B14: Server Security | C14: Secure Configuration and Change | D14: All | E14: Server configuration changes follow documented change control | F14: Is there a documented change process for server configuration (request, risk review, approval, test, rollback, post-change review) and is it followed? | G14: 2 | H14: 3 | I14: 3 | J14: =IF(IFERROR(INDEX(Scope!$C$24:$C$41,MATCH($B14,Scope!$B$24:$B$41,0)),"Yes")="No","No",IF($D14="All","Yes",IF(IFERROR(INDEX(Scope!$C$18:$C$20,MATCH($D14,Scope!$B$18:$B$20,0)),"Yes")="No","No","Yes"))) -> Yes | L14: =Scope!$C$13 -> 3 | M14: =IF(AND(J14="Yes",K14<>""),MAX(0,L14-K14),"") | N14: =IF(J14="No","N/A",IF(K14="","Not assessed",IF(K14>=L14,"Meets target","Gap"))) -> Not assessed | T14: =IF(R14<>"",R14,H14) -> 3 | U14: =IF(S14<>"",S14,I14) -> 3 | V14: =T14*U14 -> 9 | W14: =INDEX(Risk_Model!$B$30:$B$33,MATCH(V14,Risk_Model!$A$30:$A$33,1)) -> Medium | X14: =IF(OR(J14="No",K14=""),"",INDEX(Risk_Model!$C$38:$C$43,MATCH(K14,Risk_Model!$A$38:$A$43,0))) | Y14: =IF(X14="","",ROUND(V14*(1-X14),1)) | Z14: =IF(Y14="","",INDEX(Risk_Model!$B$30:$B$33,MATCH(Y14,Risk_Model!$A$30:$A$33,1))) | AA14: =IF(Y14="","",Y14+ROW()/1000000)
A15: SRV-CFG-07 | B15: Server Security | C15: Secure Configuration and Change | D15: All | E15: Only authorised software can execute or be installed on servers | F15: Is application allow-listing or equivalent execution control enforced on servers, and is software installation restricted to approved administrators and sources? | G15: 2 | H15: 3 | I15: 4 | J15: =IF(IFERROR(INDEX(Scope!$C$24:$C$41,MATCH($B15,Scope!$B$24:$B$41,0)),"Yes")="No","No",IF($D15="All","Yes",IF(IFERROR(INDEX(Scope!$C$18:$C$20,MATCH($D15,Scope!$B$18:$B$20,0)),"Yes")="No","No","Yes"))) -> Yes | L15: =Scope!$C$13 -> 3 | M15: =IF(AND(J15="Yes",K15<>""),MAX(0,L15-K15),"") | N15: =IF(J15="No","N/A",IF(K15="","Not assessed",IF(K15>=L15,"Meets target","Gap"))) -> Not assessed | T15: =IF(R15<>"",R15,H15) -> 3 | U15: =IF(S15<>"",S15,I15) -> 4 | V15: =T15*U15 -> 12 | W15: =INDEX(Risk_Model!$B$30:$B$33,MATCH(V15,Risk_Model!$A$30:$A$33,1)) -> High | X15: =IF(OR(J15="No",K15=""),"",INDEX(Risk_Model!$C$38:$C$43,MATCH(K15,Risk_Model!$A$38:$A$43,0))) | Y15: =IF(X15="","",ROUND(V15*(1-X15),1)) | Z15: =IF(Y15="","",INDEX(Risk_Model!$B$30:$B$33,MATCH(Y15,Risk_Model!$A$30:$A$33,1))) | AA15: =IF(Y15="","",Y15+ROW()/1000000)
A16: SRV-PAT-01 | B16: Server Security | C16: Patch and Lifecycle Management | D16: All | E16: A documented patch management process with risk-based timelines exists | F16: Is there a documented patch process defining roles, schedules, severity-based timelines, testing, exceptions and coverage of OS, applications and firmware? | G16: 3 | H16: 4 | I16: 5 | J16: =IF(IFERROR(INDEX(Scope!$C$24:$C$41,MATCH($B16,Scope!$B$24:$B$41,0)),"Yes")="No","No",IF($D16="All","Yes",IF(IFERROR(INDEX(Scope!$C$18:$C$20,MATCH($D16,Scope!$B$18:$B$20,0)),"Yes")="No","No","Yes"))) -> Yes | L16: =Scope!$C$13 -> 3 | M16: =IF(AND(J16="Yes",K16<>""),MAX(0,L16-K16),"") | N16: =IF(J16="No","N/A",IF(K16="","Not assessed",IF(K16>=L16,"Meets target","Gap"))) -> Not assessed | T16: =IF(R16<>"",R16,H16) -> 4 | U16: =IF(S16<>"",S16,I16) -> 5 | V16: =T16*U16 -> 20 | W16: =INDEX(Risk_Model!$B$30:$B$33,MATCH(V16,Risk_Model!$A$30:$A$33,1)) -> Critical | X16: =IF(OR(J16="No",K16=""),"",INDEX(Risk_Model!$C$38:$C$43,MATCH(K16,Risk_Model!$A$38:$A$43,0))) | Y16: =IF(X16="","",ROUND(V16*(1-X16),1)) | Z16: =IF(Y16="","",INDEX(Risk_Model!$B$30:$B$33,MATCH(Y16,Risk_Model!$A$30:$A$33,1))) | AA16: =IF(Y16="","",Y16+ROW()/1000000)
... A64: SRV-VIR-05 | B64: Server Security | C64: Virtualization Platforms | D64: Hypervisor | E64: Hypervisor logging and ransomware resilience controls are in place | F64: Are hypervisor and management logs forwarded to the SIEM, shell and SSH services disabled by default, host configuration backed up, and ransomware protections (acceptance levels, execution restrictions, datastore snapshots and backups) in place? | G64: 3 | H64: 3 | I64: 5 | J64: =IF(IFERROR(INDEX(Scope!$C$24:$C$41,MATCH($B64,Scope!$B$24:$B$41,0)),"Yes")="No","No",IF($D64="All","Yes",IF(IFERROR(INDEX(Scope!$C$18:$C$20,MATCH($D64,Scope!$B$18:$B$20,0)),"Yes")="No","No","Yes"))) -> Yes | L64: =Scope!$C$13 -> 3 | M64: =IF(AND(J64="Yes",K64<>""),MAX(0,L64-K64),"") | N64: =IF(J64="No","N/A",IF(K64="","Not assessed",IF(K64>=L64,"Meets target","Gap"))) -> Not assessed | T64: =IF(R64<>"",R64,H64) -> 3 | U64: =IF(S64<>"",S64,I64) -> 5 | V64: =T64*U64 -> 15 | W64: =INDEX(Risk_Model!$B$30:$B$33,MATCH(V64,Risk_Model!$A$30:$A$33,1)) -> High | X64: =IF(OR(J64="No",K64=""),"",INDEX(Risk_Model!$C$38:$C$43,MATCH(K64,Risk_Model!$A$38:$A$43,0))) | Y64: =IF(X64="","",ROUND(V64*(1-X64),1)) | Z64: =IF(Y64="","",INDEX(Risk_Model!$B$30:$B$33,MATCH(Y64,Risk_Model!$A$30:$A$33,1))) | AA64: =IF(Y64="","",Y64+ROW()/1000000)

Sheet Evidence_Requests
A1: Evidence Workbook - Request List (PBC)
A2: One row per evidence item required by the control library. Send to the client, track receipt, and link received items to the Evidence_Register.
A4: Request ID | B4: Control ID | C4: Control Name | D4: Evidence Item Requested | E4: Date Requested | F4: Status | G4: Date Received | H4: Evidence ID | I4: Notes
A5: ER-SRV-PHY-01-1 | B5: SRV-PHY-01 | C5: Physical access to servers is restricted and logged | D5: Authorised access list | F5: Not requested
A6: ER-SRV-PHY-01-2 | B6: SRV-PHY-01 | C6: Physical access to servers is restricted and logged | D6: badge and visitor logs (90 days) | F6: Not requested
A7: ER-SRV-PHY-01-3 | B7: SRV-PHY-01 | C7: Physical access to servers is restricted and logged | D7: CCTV coverage evidence | F7: Not requested
A8: ER-SRV-PHY-01-4 | B8: SRV-PHY-01 | C8: Physical access to servers is restricted and logged | D8: photos of rack locks | F8: Not requested
A9: ER-SRV-PHY-01-5 | B9: SRV-PHY-01 | C9: Physical access to servers is restricted and logged | D9: physical security policy | F9: Not requested
A10: ER-SRV-PHY-01-6 | B10: SRV-PHY-01 | C10: Physical access to servers is restricted and logged | D10: colocation contract and assurance report if hosted | F10: Not requested
A11: ER-SRV-PHY-02-1 | B11: SRV-PHY-02 | C11: Out-of-band management interfaces are isolated and hardened | D11: Management network diagram | F11: Not requested
A12: ER-SRV-PHY-02-2 | B12: SRV-PHY-02 | C12: Out-of-band management interfaces are isolated and hardened | D12: BMC inventory with firmware versions | F12: Not requested
A13: ER-SRV-PHY-02-3 | B13: SRV-PHY-02 | C13: Out-of-band management interfaces are isolated and hardened | D13: firewall rules for the management VLAN | F13: Not requested
A14: ER-SRV-PHY-02-4 | B14: SRV-PHY-02 | C14: Out-of-band management interfaces are isolated and hardened | D14: BMC user list and authentication settings | F14: Not requested
A15: ER-SRV-PHY-03-1 | B15: SRV-PHY-03 | C15: Removable media and unused ports are controlled | D15: GPO, MDM, udev or USBGuard configuration | F15: Not requested
A16: ER-SRV-PHY-03-2 | B16: SRV-PHY-03 | C16: Removable media and unused ports are controlled | D16: BIOS/UEFI boot-order settings | F16: Not requested
... A261: ER-SRV-VIR-05-5 | B261: SRV-VIR-05 | C261: Hypervisor logging and ransomware resilience controls are in place | D261: vendor hardening guide compliance | F261: Not requested

Sheet Evidence_Register
A1: Evidence Register
A2: Row 5 is an example. Enter evidence from row 6. Control name looks up from the Assessment sheet.
A4: Evidence ID | B4: Control ID | C4: Control Name | D4: Evidence Type | E4: Description | F4: Source System / Asset | G4: Collection Method | H4: Collected By | I4: Date Collected | J4: Storage Location / Link | K4: SHA-256 (optional) | L4: Reviewer | M4: Review Status | N4: Confidentiality
A5: EXAMPLE | B5: SRV-LOG-02 | C5: =IFERROR(INDEX(Assessment!$E$5:$E$2000,MATCH(B5,Assessment!$A$5:$A$2000,0)),"") -> Logs are forwarded in near real time to a central tamper-resistant store | D5: Screenshot | E5: SIEM log-source health dashboard showing last-seen time per server | F5: Splunk | G5: Manual | H5: A. Assessor | I5: 46296 | J5: Evidence/SRV-LOG-02/siem_health.png | L5: B. Reviewer | M5: Accepted | N5: Confidential
C6: =IF(B6="","",IFERROR(INDEX(Assessment!$E$5:$E$2000,MATCH(B6,Assessment!$A$5:$A$2000,0)),"Not found"))
C7: =IF(B7="","",IFERROR(INDEX(Assessment!$E$5:$E$2000,MATCH(B7,Assessment!$A$5:$A$2000,0)),"Not found"))
C8: =IF(B8="","",IFERROR(INDEX(Assessment!$E$5:$E$2000,MATCH(B8,Assessment!$A$5:$A$2000,0)),"Not found"))
C9: =IF(B9="","",IFERROR(INDEX(Assessment!$E$5:$E$2000,MATCH(B9,Assessment!$A$5:$A$2000,0)),"Not found"))
C10: =IF(B10="","",IFERROR(INDEX(Assessment!$E$5:$E$2000,MATCH(B10,Assessment!$A$5:$A$2000,0)),"Not found"))
C11: =IF(B11="","",IFERROR(INDEX(Assessment!$E$5:$E$2000,MATCH(B11,Assessment!$A$5:$A$2000,0)),"Not found"))
C12: =IF(B12="","",IFERROR(INDEX(Assessment!$E$5:$E$2000,MATCH(B12,Assessment!$A$5:$A$2000,0)),"Not found"))
C13: =IF(B13="","",IFERROR(INDEX(Assessment!$E$5:$E$2000,MATCH(B13,Assessment!$A$5:$A$2000,0)),"Not found"))
C14: =IF(B14="","",IFERROR(INDEX(Assessment!$E$5:$E$2000,MATCH(B14,Assessment!$A$5:$A$2000,0)),"Not found"))
C15: =IF(B15="","",IFERROR(INDEX(Assessment!$E$5:$E$2000,MATCH(B15,Assessment!$A$5:$A$2000,0)),"Not found"))
C16: =IF(B16="","",IFERROR(INDEX(Assessment!$E$5:$E$2000,MATCH(B16,Assessment!$A$5:$A$2000,0)),"Not found"))
C17: =IF(B17="","",IFERROR(INDEX(Assessment!$E$5:$E$2000,MATCH(B17,Assessment!$A$5:$A$2000,0)),"Not found"))
... C205: =IF(B205="","",IFERROR(INDEX(Assessment!$E$5:$E$2000,MATCH(B205,Assessment!$A$5:$A$2000,0)),"Not found"))

Sheet Findings_Register
A1: Findings Register
A2: Row 5 is an example. Enter findings from row 6. Open = Open or In Progress. Overdue is calculated from the due date.
A4: Finding ID | B4: Control ID | C4: Control Name | D4: Domain | E4: Finding | F4: Severity | G4: Evidence Ref(s) | H4: Recommendation | I4: Owner | J4: Due Date | K4: Status | L4: Date Raised | M4: Days Open | N4: Overdue?
A5: EXAMPLE | B5: SRV-LOG-02 | E5: Only 60% of servers forward logs to the SIEM and no alert exists for cleared Security logs. | F5: High | G5: EV-001 | H5: Deploy forwarders to all servers and create alerts for silent sources and event 1102. | I5: Infrastructure Lead | J5: 46371 | K5: Open | L5: 46297
C6: =IF(B6="","",IFERROR(INDEX(Assessment!$E$5:$E$2000,MATCH(B6,Assessment!$A$5:$A$2000,0)),"Not found")) | D6: =IF(B6="","",IFERROR(INDEX(Assessment!$B$5:$B$2000,MATCH(B6,Assessment!$A$5:$A$2000,0)),"Not found")) | M6: =IF(OR(L6="",K6="Closed",K6="Risk Accepted"),"",TODAY()-L6) | N6: =IF(OR(J6="",K6="Closed",K6="Risk Accepted",K6="Remediated"),"",IF(TODAY()>J6,"Overdue",""))
C7: =IF(B7="","",IFERROR(INDEX(Assessment!$E$5:$E$2000,MATCH(B7,Assessment!$A$5:$A$2000,0)),"Not found")) | D7: =IF(B7="","",IFERROR(INDEX(Assessment!$B$5:$B$2000,MATCH(B7,Assessment!$A$5:$A$2000,0)),"Not found")) | M7: =IF(OR(L7="",K7="Closed",K7="Risk Accepted"),"",TODAY()-L7) | N7: =IF(OR(J7="",K7="Closed",K7="Risk Accepted",K7="Remediated"),"",IF(TODAY()>J7,"Overdue",""))
C8: =IF(B8="","",IFERROR(INDEX(Assessment!$E$5:$E$2000,MATCH(B8,Assessment!$A$5:$A$2000,0)),"Not found")) | D8: =IF(B8="","",IFERROR(INDEX(Assessment!$B$5:$B$2000,MATCH(B8,Assessment!$A$5:$A$2000,0)),"Not found")) | M8: =IF(OR(L8="",K8="Closed",K8="Risk Accepted"),"",TODAY()-L8) | N8: =IF(OR(J8="",K8="Closed",K8="Risk Accepted",K8="Remediated"),"",IF(TODAY()>J8,"Overdue",""))
C9: =IF(B9="","",IFERROR(INDEX(Assessment!$E$5:$E$2000,MATCH(B9,Assessment!$A$5:$A$2000,0)),"Not found")) | D9: =IF(B9="","",IFERROR(INDEX(Assessment!$B$5:$B$2000,MATCH(B9,Assessment!$A$5:$A$2000,0)),"Not found")) | M9: =IF(OR(L9="",K9="Closed",K9="Risk Accepted"),"",TODAY()-L9) | N9: =IF(OR(J9="",K9="Closed",K9="Risk Accepted",K9="Remediated"),"",IF(TODAY()>J9,"Overdue",""))
C10: =IF(B10="","",IFERROR(INDEX(Assessment!$E$5:$E$2000,MATCH(B10,Assessment!$A$5:$A$2000,0)),"Not found")) | D10: =IF(B10="","",IFERROR(INDEX(Assessment!$B$5:$B$2000,MATCH(B10,Assessment!$A$5:$A$2000,0)),"Not found")) | M10: =IF(OR(L10="",K10="Closed",K10="Risk Accepted"),"",TODAY()-L10) | N10: =IF(OR(J10="",K10="Closed",K10="Risk Accepted",K10="Remediated"),"",IF(TODAY()>J10,"Overdue",""))
C11: =IF(B11="","",IFERROR(INDEX(Assessment!$E$5:$E$2000,MATCH(B11,Assessment!$A$5:$A$2000,0)),"Not found")) | D11: =IF(B11="","",IFERROR(INDEX(Assessment!$B$5:$B$2000,MATCH(B11,Assessment!$A$5:$A$2000,0)),"Not found")) | M11: =IF(OR(L11="",K11="Closed",K11="Risk Accepted"),"",TODAY()-L11) | N11: =IF(OR(J11="",K11="Closed",K11="Risk Accepted",K11="Remediated"),"",IF(TODAY()>J11,"Overdue",""))
C12: =IF(B12="","",IFERROR(INDEX(Assessment!$E$5:$E$2000,MATCH(B12,Assessment!$A$5:$A$2000,0)),"Not found")) | D12: =IF(B12="","",IFERROR(INDEX(Assessment!$B$5:$B$2000,MATCH(B12,Assessment!$A$5:$A$2000,0)),"Not found")) | M12: =IF(OR(L12="",K12="Closed",K12="Risk Accepted"),"",TODAY()-L12) | N12: =IF(OR(J12="",K12="Closed",K12="Risk Accepted",K12="Remediated"),"",IF(TODAY()>J12,"Overdue",""))
C13: =IF(B13="","",IFERROR(INDEX(Assessment!$E$5:$E$2000,MATCH(B13,Assessment!$A$5:$A$2000,0)),"Not found")) | D13: =IF(B13="","",IFERROR(INDEX(Assessment!$B$5:$B$2000,MATCH(B13,Assessment!$A$5:$A$2000,0)),"Not found")) | M13: =IF(OR(L13="",K13="Closed",K13="Risk Accepted"),"",TODAY()-L13) | N13: =IF(OR(J13="",K13="Closed",K13="Risk Accepted",K13="Remediated"),"",IF(TODAY()>J13,"Overdue",""))
